<sdf version='1.6'>
  <world name='default'>
    <model name='ground_plane'>
      <static>1</static>
      <link name='link'>
        <collision name='collision'>
          <geometry>
            <plane>
              <normal>0 0 1</normal>
              <size>200 200</size>
            </plane>
          </geometry>
          <surface>
            <friction>
              <ode>
                <mu>100</mu>
                <mu2>50</mu2>
              </ode>
              <torsional>
                <ode/>
              </torsional>
            </friction>
            <contact>
              <ode/>
            </contact>
            <bounce/>
          </surface>
          <max_contacts>10</max_contacts>
        </collision>
        <visual name='visual'>
          <cast_shadows>0</cast_shadows>
          <geometry>
            <plane>
              <normal>0 0 1</normal>
              <size>200 200</size>
            </plane>
          </geometry>
          <material>
            <script>
              <uri>file://media/materials/scripts/gazebo.material</uri>
              <name>Gazebo/Grey</name>
            </script>
          </material>
        </visual>
        <self_collide>0</self_collide>
        <enable_wind>0</enable_wind>
        <kinematic>0</kinematic>
      </link>
    </model>
    <light name='sun' type='directional'>
      <cast_shadows>1</cast_shadows>
      <pose frame=''>0 0 10 0 -0 0</pose>
      <diffuse>0.8 0.8 0.8 1</diffuse>
      <specular>0.2 0.2 0.2 1</specular>
      <attenuation>
        <range>1000</range>
        <constant>0.9</constant>
        <linear>0.01</linear>
        <quadratic>0.001</quadratic>
      </attenuation>
      <direction>-0.5 0.1 -0.9</direction>
    </light>
    <scene>
      <ambient>0.4 0.4 0.4 1</ambient>
      <background>0 191 255 1</background>
      <shadows>0</shadows>
    </scene>
    <gravity>0 0 -9.8</gravity>
    <magnetic_field>6e-06 2.3e-05 -4.2e-05</magnetic_field>
    <atmosphere type='adiabatic'/>
    <physics name='default_physics' default='0' type='ode'>
      <max_step_size>0.001</max_step_size>
      <real_time_factor>1</real_time_factor>
      <real_time_update_rate>1000</real_time_update_rate>
    </physics>
    <wind/>
    <spherical_coordinates>
      <surface_model>EARTH_WGS84</surface_model>
      <latitude_deg>0</latitude_deg>
      <longitude_deg>0</longitude_deg>
      <elevation>0</elevation>
      <heading_deg>0</heading_deg>
    </spherical_coordinates>
    <model name='door_1'>
      <link name='hinge'>
        <pose frame=''>0 0 0 0 -0 0</pose>
        <inertial>
          <pose frame=''>-0.05 0 0 0 -0 0</pose>
          <mass>0.5</mass>
          <inertia>
            <ixx>1</ixx>
            <ixy>0</ixy>
            <ixz>0</ixz>
            <iyy>100</iyy>
            <iyz>0</iyz>
            <izz>1</izz>
          </inertia>
        </inertial>
        <velocity_decay>
          <linear>0</linear>
          <angular>0</angular>
        </velocity_decay>
        <self_collide>0</self_collide>
        <enable_wind>0</enable_wind>
        <kinematic>0</kinematic>
      </link>
      <link name='door'>
        <pose frame=''>0.05 -0.2 0.35 0 0 -1.57</pose>
        <inertial>
          <pose frame=''>0.05 -0.2 0.35 0 0 -1.57</pose>
          <mass>5</mass>
          <inertia>
            <ixx>1</ixx>
            <ixy>0</ixy>
            <ixz>0</ixz>
            <iyy>100</iyy>
            <iyz>0</iyz>
            <izz>1</izz>
          </inertia>
        </inertial>
        <collision name='door_collision'>
          <pose frame=''>0.05 -0.2 0.35 0 0 -1.57</pose>
          <geometry>
            <box>
              <size>0.927 0.1 1.96</size>
            </box>
          </geometry>
          <surface>
            <contact>
              <ode/>
            </contact>
            <friction>
              <ode/>
              <torsional>
                <ode/>
              </torsional>
            </friction>
            <bounce/>
          </surface>
          <max_contacts>10</max_contacts>
        </collision>
        <visual name='door_visual'>
          <pose frame=''>0.05 -0.2 0.35 0 0 -1.57</pose>
          <geometry>
            <box>
              <size>0.927 0.1 1.96</size>
            </box>
          </geometry>
          <material>
            <script>
              <name>Gazebo/Red</name>
              <uri>__default__</uri>
            </script>
          </material>
        </visual>
        <gravity>1</gravity>
        <velocity_decay>
          <linear>0</linear>
          <angular>0</angular>
        </velocity_decay>
        <self_collide>0</self_collide>
        <enable_wind>0</enable_wind>
        <kinematic>0</kinematic>
      </link>
      <joint name='door_hinge' type='revolute'>
        <child>door</child>
        <parent>hinge</parent>
        <pose frame=''>0.08 0 0 0 -0 0</pose>
        <axis>
          <xyz>0 0 1</xyz>
          <limit>
            <lower>-1.57</lower>
            <upper>0</upper>
            <effort>0</effort>
            <velocity>10</velocity>
          </limit>
          <dynamics>
            <spring_reference>0</spring_reference>
            <spring_stiffness>0</spring_stiffness>
          </dynamics>
          <use_parent_model_frame>0</use_parent_model_frame>
        </axis>
      </joint>
      <joint name='floor_link' type='revolute'>
        <child>hinge</child>
        <parent>world</parent>
        <axis>
          <xyz>0 0 1</xyz>
          <limit>
            <lower>0</lower>
            <upper>0</upper>
            <effort>0</effort>
            <velocity>0</velocity>
          </limit>
          <dynamics>
            <spring_reference>0</spring_reference>
            <spring_stiffness>0</spring_stiffness>
          </dynamics>
          <use_parent_model_frame>0</use_parent_model_frame>
        </axis>
      </joint>
      <plugin name='door_plugin' filename='libdoor_plugin.so'>
        <door_type>flip</door_type>
        <model_domain_space>door_</model_domain_space>
        <door_direction>clockwise</door_direction>
        <robotNamespace>/</robotNamespace>
      </plugin>
      <pose frame=''>-3.04236 5.53278 0.3 0 -0 0</pose>
    </model>
    <model name='door_2'>
      <link name='hinge'>
        <pose frame=''>0 0 0 0 -0 0</pose>
        <inertial>
          <pose frame=''>-0.05 0 0 0 -0 0</pose>
          <mass>0.5</mass>
          <inertia>
            <ixx>1</ixx>
            <ixy>0</ixy>
            <ixz>0</ixz>
            <iyy>100</iyy>
            <iyz>0</iyz>
            <izz>1</izz>
          </inertia>
        </inertial>
        <velocity_decay>
          <linear>0</linear>
          <angular>0</angular>
        </velocity_decay>
        <self_collide>0</self_collide>
        <enable_wind>0</enable_wind>
        <kinematic>0</kinematic>
      </link>
      <link name='door'>
        <pose frame=''>0.05 0.2 0.35 0 0 -1.57</pose>
        <inertial>
          <pose frame=''>0.05 0.2 0.35 0 0 -1.57</pose>
          <mass>5</mass>
          <inertia>
            <ixx>1</ixx>
            <ixy>0</ixy>
            <ixz>0</ixz>
            <iyy>100</iyy>
            <iyz>0</iyz>
            <izz>1</izz>
          </inertia>
        </inertial>
        <collision name='door_collision'>
          <pose frame=''>0.05 0.2 0.35 0 0 -1.57</pose>
          <geometry>
            <box>
              <size>0.927 0.1 1.96</size>
            </box>
          </geometry>
          <surface>
            <contact>
              <ode/>
            </contact>
            <friction>
              <ode/>
              <torsional>
                <ode/>
              </torsional>
            </friction>
            <bounce/>
          </surface>
          <max_contacts>10</max_contacts>
        </collision>
        <visual name='door_visual'>
          <pose frame=''>0.05 0.2 0.35 0 0 -1.57</pose>
          <geometry>
            <box>
              <size>0.927 0.1 1.96</size>
            </box>
          </geometry>
          <material>
            <script>
              <name>Gazebo/Red</name>
              <uri>__default__</uri>
            </script>
          </material>
        </visual>
        <gravity>1</gravity>
        <velocity_decay>
          <linear>0</linear>
          <angular>0</angular>
        </velocity_decay>
        <self_collide>0</self_collide>
        <enable_wind>0</enable_wind>
        <kinematic>0</kinematic>
      </link>
      <joint name='door_hinge' type='revolute'>
        <child>door</child>
        <parent>hinge</parent>
        <pose frame=''>0.08 0 0 0 -0 0</pose>
        <axis>
          <xyz>0 0 1</xyz>
          <limit>
            <lower>0</lower>
            <upper>1.57</upper>
            <effort>0</effort>
            <velocity>10</velocity>
          </limit>
          <dynamics>
            <spring_reference>0</spring_reference>
            <spring_stiffness>0</spring_stiffness>
          </dynamics>
          <use_parent_model_frame>0</use_parent_model_frame>
        </axis>
      </joint>
      <joint name='floor_link' type='revolute'>
        <child>hinge</child>
        <parent>world</parent>
        <axis>
          <xyz>0 0 1</xyz>
          <limit>
            <lower>0</lower>
            <upper>0</upper>
            <effort>0</effort>
            <velocity>0</velocity>
          </limit>
          <dynamics>
            <spring_reference>0</spring_reference>
            <spring_stiffness>0</spring_stiffness>
          </dynamics>
          <use_parent_model_frame>0</use_parent_model_frame>
        </axis>
      </joint>
      <plugin name='door_plugin' filename='libdoor_plugin.so'>
        <door_type>flip</door_type>
        <model_domain_space>door_</model_domain_space>
        <door_direction>counter_clockwise</door_direction>
        <robotNamespace>/</robotNamespace>
      </plugin>
      <pose frame=''>-4.45233 5.07849 0.3 0 -0 0</pose>
    </model>
    <model name='stairs'>
      <pose frame=''>-15.9367 1.1204 0 0 -0 0</pose>
      <static>1</static>
      <link name='link'>
        <collision name='collision'>
          <geometry>
            <mesh>
              <uri>model://urban/meshes/Urban_Circuit_LowRes_Scan_alpha_UpperFloor.dae</uri>
            </mesh>
          </geometry>
          <max_contacts>10</max_contacts>
          <surface>
            <contact>
              <ode/>
            </contact>
            <bounce/>
            <friction>
              <torsional>
                <ode/>
              </torsional>
              <ode/>
            </friction>
          </surface>
        </collision>
        <visual name='visual'>
          <geometry>
            <mesh>
              <uri>model://urban/meshes/Urban_Circuit_LowRes_Scan_alpha_UpperFloor.dae</uri>
            </mesh>
          </geometry>
        </visual>
        <self_collide>0</self_collide>
        <enable_wind>0</enable_wind>
        <kinematic>0</kinematic>
      </link>
    </model>
    <state world_name='default'>
      <sim_time>480 591000000</sim_time>
      <real_time>497 579586448</real_time>
      <wall_time>1640095627 176460106</wall_time>
      <iterations>480591</iterations>
      <model name='door_1'>
        <pose frame=''>-3.04236 5.53278 0.3 -0 -0 -0</pose>
        <scale>1 1 1</scale>
        <link name='door'>
          <pose frame=''>-2.98809 5.33267 0.65 0 0 -1.62344</pose>
          <velocity>-0 -0 0 0 -0 0</velocity>
          <acceleration>-4.9e-05 -4e-06 0 0 -0 -1.3e-05</acceleration>
          <wrench>-0.000244 -1.8e-05 0 0 -0 0</wrench>
        </link>
        <link name='hinge'>
          <pose frame=''>-3.04236 5.53278 0.3 -0 -0 -0</pose>
          <velocity>-0 0 -0 -0 -0 -0</velocity>
          <acceleration>-0 9e-06 -0 -0 -0 -0.000178</acceleration>
          <wrench>-0 4e-06 -0 0 -0 0</wrench>
        </link>
      </model>
      <model name='door_2'>
        <pose frame=''>-4.45233 5.07849 0.3 0 -0 0</pose>
        <scale>1 1 1</scale>
        <link name='door'>
          <pose frame=''>-4.4024 5.27849 0.65 -0 -0 -1.56918</pose>
          <velocity>0 -0 -0 0 -0 0</velocity>
          <acceleration>9e-06 -2e-06 -0 0 -0 4e-06</acceleration>
          <wrench>4.7e-05 -1.2e-05 -0 0 -0 0</wrench>
        </link>
        <link name='hinge'>
          <pose frame=''>-4.45233 5.07849 0.3 0 -0 0</pose>
          <velocity>0 -0 0 0 -0 0</velocity>
          <acceleration>0 4e-06 0 0 0 -8e-05</acceleration>
          <wrench>0 2e-06 0 0 -0 0</wrench>
        </link>
      </model>
      <model name='ground_plane'>
        <pose frame=''>0 0 0 0 -0 0</pose>
        <scale>1 1 1</scale>
        <link name='link'>
          <pose frame=''>0 0 0 0 -0 0</pose>
          <velocity>0 0 0 0 -0 0</velocity>
          <acceleration>0 0 0 0 -0 0</acceleration>
          <wrench>0 0 0 0 -0 0</wrench>
        </link>
      </model>
      <model name='stairs'>
        <pose frame=''>-17.1198 -10.8141 0 0 -0 0</pose>
        <scale>1 1 1</scale>
        <link name='link'>
          <pose frame=''>-17.1198 -10.8141 0 0 -0 0</pose>
          <velocity>0 0 0 0 -0 0</velocity>
          <acceleration>0 0 0 0 -0 0</acceleration>
          <wrench>0 0 0 0 -0 0</wrench>
        </link>
      </model>
      <light name='sun'>
        <pose frame=''>0 0 10 0 -0 0</pose>
      </light>
    </state>
    <gui fullscreen='0'>
      <camera name='user_camera'>
        <pose frame=''>-4.95021 -1.32463 1.76594 0 0.183648 1.32317</pose>
        <view_controller>orbit</view_controller>
        <projection_type>perspective</projection_type>
      </camera>
    </gui>
  </world>
</sdf>
